submitit ERROR (2021-08-08 22:16:48,093) - Submitted job triggered an exception
Traceback (most recent call last):
  File "/usr/lib/python3.8/runpy.py", line 194, in _run_module_as_main
    return _run_code(code, main_globals, None,
  File "/usr/lib/python3.8/runpy.py", line 87, in _run_code
    exec(code, run_globals)
  File "/work/dlclarge2/agnihotr-shashank-pruneshift/debug/debug/lib/python3.8/site-packages/submitit/core/_submit.py", line 11, in <module>
    submitit_main()
  File "/work/dlclarge2/agnihotr-shashank-pruneshift/debug/debug/lib/python3.8/site-packages/submitit/core/submission.py", line 71, in submitit_main
    process_job(args.folder)
  File "/work/dlclarge2/agnihotr-shashank-pruneshift/debug/debug/lib/python3.8/site-packages/submitit/core/submission.py", line 64, in process_job
    raise error
  File "/work/dlclarge2/agnihotr-shashank-pruneshift/debug/debug/lib/python3.8/site-packages/submitit/core/submission.py", line 53, in process_job
    result = delayed.result()
  File "/work/dlclarge2/agnihotr-shashank-pruneshift/debug/debug/lib/python3.8/site-packages/submitit/core/utils.py", line 126, in result
    self._result = self.function(*self.args, **self.kwargs)
  File "<ipython-input-3-5b5f25d476fa>", line 43, in collect_samples
  File "/work/dlclarge2/agnihotr-shashank-pruneshift/pruneshift/src/pruneshift/networks.py", line 112, in create_network
    network = network_fn(num_classes=create_num_classes, **kwargs)
  File "/work/dlclarge2/agnihotr-shashank-pruneshift/debug/debug/lib/python3.8/site-packages/torchvision/models/resnet.py", line 276, in resnet18
    return _resnet('resnet18', BasicBlock, [2, 2, 2, 2], pretrained, progress,
  File "/work/dlclarge2/agnihotr-shashank-pruneshift/debug/debug/lib/python3.8/site-packages/torchvision/models/resnet.py", line 260, in _resnet
    model = ResNet(block, layers, **kwargs)
TypeError: __init__() got an unexpected keyword argument 'imagenet_subset'
srun: error: dlcgpu24: task 0: Exited with exit code 1
