submitit ERROR (2021-08-13 04:37:36,999) - Submitted job triggered an exception
Traceback (most recent call last):
  File "/usr/lib/python3.8/runpy.py", line 194, in _run_module_as_main
    return _run_code(code, main_globals, None,
  File "/usr/lib/python3.8/runpy.py", line 87, in _run_code
    exec(code, run_globals)
  File "/work/dlclarge2/agnihotr-shashank-pruneshift/debug/debug/lib/python3.8/site-packages/submitit/core/_submit.py", line 11, in <module>
    submitit_main()
  File "/work/dlclarge2/agnihotr-shashank-pruneshift/debug/debug/lib/python3.8/site-packages/submitit/core/submission.py", line 71, in submitit_main
    process_job(args.folder)
  File "/work/dlclarge2/agnihotr-shashank-pruneshift/debug/debug/lib/python3.8/site-packages/submitit/core/submission.py", line 64, in process_job
    raise error
  File "/work/dlclarge2/agnihotr-shashank-pruneshift/debug/debug/lib/python3.8/site-packages/submitit/core/submission.py", line 53, in process_job
    result = delayed.result()
  File "/work/dlclarge2/agnihotr-shashank-pruneshift/debug/debug/lib/python3.8/site-packages/submitit/core/utils.py", line 126, in result
    self._result = self.function(*self.args, **self.kwargs)
  File "<ipython-input-20-74f942efb16f>", line 53, in collect_samples
  File "/work/dlclarge2/agnihotr-shashank-pruneshift/pruneshift/src/pruneshift/network_markers.py", line 44, in classifier
    network=network.network
  File "/work/dlclarge2/agnihotr-shashank-pruneshift/debug/debug/lib/python3.8/site-packages/torch/nn/modules/module.py", line 947, in __getattr__
    raise AttributeError("'{}' object has no attribute '{}'".format(
AttributeError: 'Sequential' object has no attribute 'network'
srun: error: dlcgpu26: task 0: Exited with exit code 1
